2022-01-17 16:18:46,613 ERROR: Exception on /static/images/logo/yasf-logo-2.svg [GET] [in /workspaces/flask-saas-framework/.venv/lib/python3.8/site-packages/flask/app.py:1454]
Traceback (most recent call last):
  File "/workspaces/flask-saas-framework/.venv/lib/python3.8/site-packages/flask/app.py", line 1513, in full_dispatch_request
    rv = self.dispatch_request()
  File "/workspaces/flask-saas-framework/.venv/lib/python3.8/site-packages/flask/app.py", line 1499, in dispatch_request
    return self.ensure_sync(self.view_functions[rule.endpoint])(**req.view_args)
  File "/workspaces/flask-saas-framework/.venv/lib/python3.8/site-packages/flask/app.py", line 518, in <lambda>
    view_func=lambda **kw: self_ref().send_static_file(**kw),  # type: ignore # noqa: B950
  File "/workspaces/flask-saas-framework/.venv/lib/python3.8/site-packages/flask/scaffold.py", line 328, in send_static_file
    return send_from_directory(
  File "/workspaces/flask-saas-framework/.venv/lib/python3.8/site-packages/flask/helpers.py", line 700, in send_from_directory
    return werkzeug.utils.send_from_directory(  # type: ignore
  File "/workspaces/flask-saas-framework/.venv/lib/python3.8/site-packages/werkzeug/utils.py", line 841, in send_from_directory
    raise NotFound()
werkzeug.exceptions.NotFound: 404 Not Found: The requested URL was not found on the server. If you entered the URL manually please check your spelling and try again.

During handling of the above exception, another exception occurred:

Traceback (most recent call last):
  File "/workspaces/flask-saas-framework/.venv/lib/python3.8/site-packages/flask/app.py", line 2070, in wsgi_app
    response = self.full_dispatch_request()
  File "/workspaces/flask-saas-framework/.venv/lib/python3.8/site-packages/flask/app.py", line 1515, in full_dispatch_request
    rv = self.handle_user_exception(e)
  File "/workspaces/flask-saas-framework/.venv/lib/python3.8/site-packages/flask/app.py", line 1383, in handle_user_exception
    return self.handle_http_exception(e)
  File "/workspaces/flask-saas-framework/.venv/lib/python3.8/site-packages/flask/app.py", line 1323, in handle_http_exception
    return self.ensure_sync(handler)(e)
  File "/workspaces/flask-saas-framework/app/errors/handlers.py", line 8, in not_found_error
    return render_template('errors/404.html'), 404
  File "/workspaces/flask-saas-framework/.venv/lib/python3.8/site-packages/flask/templating.py", line 147, in render_template
    return _render(
  File "/workspaces/flask-saas-framework/.venv/lib/python3.8/site-packages/flask/templating.py", line 128, in _render
    rv = template.render(context)
  File "/workspaces/flask-saas-framework/.venv/lib/python3.8/site-packages/jinja2/environment.py", line 1304, in render
    self.environment.handle_exception()
  File "/workspaces/flask-saas-framework/.venv/lib/python3.8/site-packages/jinja2/environment.py", line 925, in handle_exception
    raise rewrite_traceback_stack(source=source)
  File "/workspaces/flask-saas-framework/app/templates/errors/404.html", line 1, in top-level template code
    {% extends "landing/base.html" %}
  File "/workspaces/flask-saas-framework/app/templates/landing/base.html", line 44, in top-level template code
    {% block content %}
  File "/workspaces/flask-saas-framework/app/templates/landing/base.html", line 71, in block 'content'
    {% if 'auth' in url_for(request.endpoint) %}
  File "/workspaces/flask-saas-framework/.venv/lib/python3.8/site-packages/flask/helpers.py", line 338, in url_for
    return appctx.app.handle_url_build_error(error, endpoint, values)
  File "/workspaces/flask-saas-framework/.venv/lib/python3.8/site-packages/flask/helpers.py", line 325, in url_for
    rv = url_adapter.build(
  File "/workspaces/flask-saas-framework/.venv/lib/python3.8/site-packages/werkzeug/routing.py", line 2305, in build
    raise BuildError(endpoint, values, method, self)
werkzeug.routing.BuildError: Could not build url for endpoint 'static'. Did you forget to specify values ['filename']?
2022-01-17 16:18:46,621 ERROR: Exception on /static/images/logo/yasf-logo.svg [GET] [in /workspaces/flask-saas-framework/.venv/lib/python3.8/site-packages/flask/app.py:1454]
Traceback (most recent call last):
  File "/workspaces/flask-saas-framework/.venv/lib/python3.8/site-packages/flask/app.py", line 1513, in full_dispatch_request
    rv = self.dispatch_request()
  File "/workspaces/flask-saas-framework/.venv/lib/python3.8/site-packages/flask/app.py", line 1499, in dispatch_request
    return self.ensure_sync(self.view_functions[rule.endpoint])(**req.view_args)
  File "/workspaces/flask-saas-framework/.venv/lib/python3.8/site-packages/flask/app.py", line 518, in <lambda>
    view_func=lambda **kw: self_ref().send_static_file(**kw),  # type: ignore # noqa: B950
  File "/workspaces/flask-saas-framework/.venv/lib/python3.8/site-packages/flask/scaffold.py", line 328, in send_static_file
    return send_from_directory(
  File "/workspaces/flask-saas-framework/.venv/lib/python3.8/site-packages/flask/helpers.py", line 700, in send_from_directory
    return werkzeug.utils.send_from_directory(  # type: ignore
  File "/workspaces/flask-saas-framework/.venv/lib/python3.8/site-packages/werkzeug/utils.py", line 841, in send_from_directory
    raise NotFound()
werkzeug.exceptions.NotFound: 404 Not Found: The requested URL was not found on the server. If you entered the URL manually please check your spelling and try again.

During handling of the above exception, another exception occurred:

Traceback (most recent call last):
  File "/workspaces/flask-saas-framework/.venv/lib/python3.8/site-packages/flask/app.py", line 2070, in wsgi_app
    response = self.full_dispatch_request()
  File "/workspaces/flask-saas-framework/.venv/lib/python3.8/site-packages/flask/app.py", line 1515, in full_dispatch_request
    rv = self.handle_user_exception(e)
  File "/workspaces/flask-saas-framework/.venv/lib/python3.8/site-packages/flask/app.py", line 1383, in handle_user_exception
    return self.handle_http_exception(e)
  File "/workspaces/flask-saas-framework/.venv/lib/python3.8/site-packages/flask/app.py", line 1323, in handle_http_exception
    return self.ensure_sync(handler)(e)
  File "/workspaces/flask-saas-framework/app/errors/handlers.py", line 8, in not_found_error
    return render_template('errors/404.html'), 404
  File "/workspaces/flask-saas-framework/.venv/lib/python3.8/site-packages/flask/templating.py", line 147, in render_template
    return _render(
  File "/workspaces/flask-saas-framework/.venv/lib/python3.8/site-packages/flask/templating.py", line 128, in _render
    rv = template.render(context)
  File "/workspaces/flask-saas-framework/.venv/lib/python3.8/site-packages/jinja2/environment.py", line 1304, in render
    self.environment.handle_exception()
  File "/workspaces/flask-saas-framework/.venv/lib/python3.8/site-packages/jinja2/environment.py", line 925, in handle_exception
    raise rewrite_traceback_stack(source=source)
  File "/workspaces/flask-saas-framework/app/templates/errors/404.html", line 1, in top-level template code
    {% extends "landing/base.html" %}
  File "/workspaces/flask-saas-framework/app/templates/landing/base.html", line 44, in top-level template code
    {% block content %}
  File "/workspaces/flask-saas-framework/app/templates/landing/base.html", line 71, in block 'content'
    {% if 'auth' in url_for(request.endpoint) %}
  File "/workspaces/flask-saas-framework/.venv/lib/python3.8/site-packages/flask/helpers.py", line 338, in url_for
    return appctx.app.handle_url_build_error(error, endpoint, values)
  File "/workspaces/flask-saas-framework/.venv/lib/python3.8/site-packages/flask/helpers.py", line 325, in url_for
    rv = url_adapter.build(
  File "/workspaces/flask-saas-framework/.venv/lib/python3.8/site-packages/werkzeug/routing.py", line 2305, in build
    raise BuildError(endpoint, values, method, self)
werkzeug.routing.BuildError: Could not build url for endpoint 'static'. Did you forget to specify values ['filename']?
